Error generating AI response: PermissionDeniedError: 403 Project `proj_A5bsgwzADD82zMnP321e85xn` does not have access to model `gpt-4`
    at Function.generate (/home/runner/workspace/node_modules/openai/src/error.ts:80:14)
    at OpenAI.makeStatusError (/home/runner/workspace/node_modules/openai/src/core.ts:435:21)
    at OpenAI.makeRequest (/home/runner/workspace/node_modules/openai/src/core.ts:499:24)
    at process.processTicksAndRejections (node:internal/process/task_queues:95:5)
    at async generateAIResponse (/home/runner/workspace/server/services/ai.ts:80:22)
    at async <anonymous> (/home/runner/workspace/server/routes.ts:508:24) {
  status: 403,
  headers: {
    'alt-svc': 'h3=":443"; ma=86400',
    'cf-cache-status': 'DYNAMIC',
    'cf-ray': '90b6fb59b8887bba-ATL',
    connection: 'keep-alive',
    'content-encoding': 'gzip',
    'content-type': 'application/json; charset=utf-8',
    date: 'Sun, 02 Feb 2025 03:09:20 GMT',
    server: 'cloudflare',
    'set-cookie': '__cf_bm=DVwrGlEo5Sx7XbRu28oFhUDZz9z_l2nSSWrvNMqsEoc-1738465760-1.0.1.1-Tacwf7NaH.L.rkujrCpwaB_eAWS2e.jRs3xU1fMBiDUKPzUaW1S9YN0bdyqrJF480e1xkQmn6YvlPhxWXnmkDA; path=/; expires=Sun, 02-Feb-25 03:39:20 GMT; domain=.api.openai.com; HttpOnly; Secure; SameSite=None, _cfuvid=ZAXpNd.rbFZjNnAnek20LVzmv0cWdaZUzy6NDLxRFMc-1738465760321-0.0.1.1-604800000; path=/; domain=.api.openai.com; HttpOnly; Secure; SameSite=None',
    'strict-transport-security': 'max-age=31536000; includeSubDomains; preload',
    'transfer-encoding': 'chunked',
    vary: 'Origin',
    'x-content-type-options': 'nosniff',
    'x-request-id': 'req_5dfda24109098a323b7456fa76901777'
  },
  request_id: 'req_5dfda24109098a323b7456fa76901777',
  error: {
    message: 'Project `proj_A5bsgwzADD82zMnP321e85xn` does not have access to model `gpt-4`',
    type: 'invalid_request_error',
    param: null,
    code: 'model_not_found'
  },
  code: 'model_not_found',
  param: null,
  type: 'invalid_request_error'
}
Chat error: PermissionDeniedError: 403 Project `proj_A5bsgwzADD82zMnP321e85xn` does not have access to model `gpt-4`
    at Function.generate (/home/runner/workspace/node_modules/openai/src/error.ts:80:14)
    at OpenAI.makeStatusError (/home/runner/workspace/node_modules/openai/src/core.ts:435:21)
    at OpenAI.makeRequest (/home/runner/workspace/node_modules/openai/src/core.ts:499:24)
    at process.processTicksAndRejections (node:internal/process/task_queues:95:5)
    at async generateAIResponse (/home/runner/workspace/server/services/ai.ts:80:22)
    at async <anonymous> (/home/runner/workspace/server/routes.ts:508:24) {
  status: 403,
  headers: {
    'alt-svc': 'h3=":443"; ma=86400',
    'cf-cache-status': 'DYNAMIC',
    'cf-ray': '90b6fb59b8887bba-ATL',
    connection: 'keep-alive',
    'content-encoding': 'gzip',
    'content-type': 'application/json; charset=utf-8',
    date: 'Sun, 02 Feb 2025 03:09:20 GMT',
    server: 'cloudflare',
    'set-cookie': '__cf_bm=DVwrGlEo5Sx7XbRu28oFhUDZz9z_l2nSSWrvNMqsEoc-1738465760-1.0.1.1-Tacwf7NaH.L.rkujrCpwaB_eAWS2e.jRs3xU1fMBiDUKPzUaW1S9YN0bdyqrJF480e1xkQmn6YvlPhxWXnmkDA; path=/; expires=Sun, 02-Feb-25 03:39:20 GMT; domain=.api.openai.com; HttpOnly; Secure; SameSite=None, _cfuvid=ZAXpNd.rbFZjNnAnek20LVzmv0cWdaZUzy6NDLxRFMc-1738465760321-0.0.1.1-604800000; path=/; domain=.api.openai.com; HttpOnly; Secure; SameSite=None',
    'strict-transport-security': 'max-age=31536000; includeSubDomains; preload',
    'transfer-encoding': 'chunked',
    vary: 'Origin',
    'x-content-type-options': 'nosniff',
    'x-request-id': 'req_5dfda24109098a323b7456fa76901777'
  },
  request_id: 'req_5dfda24109098a323b7456fa76901777',
  error: {
    message: 'Project `proj_A5bsgwzADD82zMnP321e85xn` does not have access to model `gpt-4`',
    type: 'invalid_request_error',
    param: null,
    code: 'model_not_found'
  },
  code: 'model_not_found',
  param: null,
  type: 'invalid_request_error'
}